 * Serving Flask app 'server'
 * Debug mode: off
WARNING: This is a development server. Do not use it in a production deployment. Use a production WSGI server instead.
 * Running on all addresses (0.0.0.0)
 * Running on http://127.0.0.1:5000
 * Running on http://10.244.0.11:5000
Press CTRL+C to quit
[2025-06-20 18:56:16,451[] ERROR in app: Exception on /login [POST]
Traceback (most recent call last):
  File "/usr/local/lib/python3.13/site-packages/flask/app.py", line 1511, in wsgi_app
    response = self.full_dispatch_request()
  File "/usr/local/lib/python3.13/site-packages/flask/app.py", line 919, in full_dispatch_request
    rv = self.handle_user_exception(e)
  File "/usr/local/lib/python3.13/site-packages/flask/app.py", line 917, in full_dispatch_request
    rv = self.dispatch_request()
  File "/usr/local/lib/python3.13/site-packages/flask/app.py", line 902, in dispatch_request
    return self.ensure_sync(self.view_functions[rule.endpoint[])(**view_args)  # type: ignore[no-any-return]
           ~~~~~~~~~~~~~~~~~~~~~~~~~~~~~~~~~~~~~~~~~~~~~~~~~~~~^^^^^^^^^^^^^
  File "/app/server.py", line 23, in login
    cursor = mysql.connection.cursor()
             ^^^^^^^^^^^^^^^^
  File "/usr/local/lib/python3.13/site-packages/flask_mysqldb/__init__.py", line 109, in connection
    ctx.mysql_db = self.connect
                   ^^^^^^^^^^^^
  File "/usr/local/lib/python3.13/site-packages/flask_mysqldb/__init__.py", line 97, in connect
    return MySQLdb.connect(**kwargs)
           ~~~~~~~~~~~~~~~^^^^^^^^^^
  File "/usr/local/lib/python3.13/site-packages/MySQLdb/__init__.py", line 121, in Connect
    return Connection(*args, **kwargs)
  File "/usr/local/lib/python3.13/site-packages/MySQLdb/connections.py", line 200, in __init__
    super().__init__(*args, **kwargs2)
    ~~~~~~~~~~~~~~~~^^^^^^^^^^^^^^^^^^
MySQLdb.OperationalError: (1045, "Access denied for user 'auth_user'@'localhost' (using password: YES)")
10.244.0.45 - - [20/Jun/2025 18:56:16] "POST /login HTTP/1.1" 500 -
[2025-06-20 18:58:17,581[] ERROR in app: Exception on /login [POST]
Traceback (most recent call last):
  File "/usr/local/lib/python3.13/site-packages/flask/app.py", line 1511, in wsgi_app
    response = self.full_dispatch_request()
  File "/usr/local/lib/python3.13/site-packages/flask/app.py", line 919, in full_dispatch_request
    rv = self.handle_user_exception(e)
  File "/usr/local/lib/python3.13/site-packages/flask/app.py", line 917, in full_dispatch_request
    rv = self.dispatch_request()
  File "/usr/local/lib/python3.13/site-packages/flask/app.py", line 902, in dispatch_request
    return self.ensure_sync(self.view_functions[rule.endpoint[])(**view_args)  # type: ignore[no-any-return]
           ~~~~~~~~~~~~~~~~~~~~~~~~~~~~~~~~~~~~~~~~~~~~~~~~~~~~^^^^^^^^^^^^^
  File "/app/server.py", line 23, in login
    cursor = mysql.connection.cursor()
             ^^^^^^^^^^^^^^^^
  File "/usr/local/lib/python3.13/site-packages/flask_mysqldb/__init__.py", line 109, in connection
    ctx.mysql_db = self.connect
                   ^^^^^^^^^^^^
  File "/usr/local/lib/python3.13/site-packages/flask_mysqldb/__init__.py", line 97, in connect
    return MySQLdb.connect(**kwargs)
           ~~~~~~~~~~~~~~~^^^^^^^^^^
  File "/usr/local/lib/python3.13/site-packages/MySQLdb/__init__.py", line 121, in Connect
    return Connection(*args, **kwargs)
  File "/usr/local/lib/python3.13/site-packages/MySQLdb/connections.py", line 200, in __init__
    super().__init__(*args, **kwargs2)
    ~~~~~~~~~~~~~~~~^^^^^^^^^^^^^^^^^^
MySQLdb.OperationalError: (1045, "Access denied for user 'auth_user'@'localhost' (using password: YES)")
10.244.0.44 - - [20/Jun/2025 18:58:17] "POST /login HTTP/1.1" 500 -
